<?xml version="1.0" ?>
<!-- =================================================================================== -->
<!-- |    This document was autogenerated by xacro from navbot.xacro                   | -->
<!-- |    EDITING THIS FILE BY HAND IS NOT RECOMMENDED                                 | -->
<!-- =================================================================================== -->
<robot name="navbot">
  <material name="silver">
    <color rgba="0.700 0.700 0.700 1.000"/>
  </material>
  <transmission name="Rev1_tran">
    <type>transmission_interface/SimpleTransmission</type>
    <joint name="Rev1">
      <hardwareInterface>hardware_interface/VelocityJointInterface</hardwareInterface>
    </joint>
    <actuator name="Rev1_actr">
      <hardwareInterface>hardware_interface/EffortJointInterface</hardwareInterface>
      <mechanicalReduction>1</mechanicalReduction>
    </actuator>
  </transmission>
  <transmission name="Rev3_tran">
    <type>transmission_interface/SimpleTransmission</type>
    <joint name="Rev3">
      <hardwareInterface>hardware_interface/VelocityJointInterface</hardwareInterface>
    </joint>
    <actuator name="Rev3_actr">
      <hardwareInterface>hardware_interface/EffortJointInterface</hardwareInterface>
      <mechanicalReduction>1</mechanicalReduction>
    </actuator>
  </transmission>
  <transmission name="Rev4_tran">
    <type>transmission_interface/SimpleTransmission</type>
    <joint name="Rev4">
      <hardwareInterface>hardware_interface/VelocityJointInterface</hardwareInterface>
    </joint>
    <actuator name="Rev4_actr">
      <hardwareInterface>hardware_interface/EffortJointInterface</hardwareInterface>
      <mechanicalReduction>1</mechanicalReduction>
    </actuator>
  </transmission>
  <transmission name="Rev5_tran">
    <type>transmission_interface/SimpleTransmission</type>
    <joint name="Rev5">
      <hardwareInterface>hardware_interface/VelocityJointInterface</hardwareInterface>
    </joint>
    <actuator name="Rev5_actr">
      <hardwareInterface>hardware_interface/EffortJointInterface</hardwareInterface>
      <mechanicalReduction>1</mechanicalReduction>
    </actuator>
  </transmission>
  <gazebo>
    <plugin filename="libgazebo_ros_control.so" name="gazebo_ros_control">
      <robotNamespace>/navbot</robotNamespace>
    </plugin>
  </gazebo>
  <gazebo reference="base_link">
    <material>Gazebo/Silver</material>
    <mu1>0.2</mu1>
    <mu2>0.2</mu2>
    <selfCollide>true</selfCollide>
    <gravity>true</gravity>
  </gazebo>
  <gazebo reference="back_right_1">
    <material>Gazebo/Silver</material>
    <mu1>0.2</mu1>
    <mu2>0.2</mu2>
    <selfCollide>true</selfCollide>
  </gazebo>
  <gazebo reference="front_right_1">
    <material>Gazebo/Silver</material>
    <mu1>0.2</mu1>
    <mu2>0.2</mu2>
    <selfCollide>true</selfCollide>
  </gazebo>
  <gazebo reference="back_left_1">
    <material>Gazebo/Silver</material>
    <mu1>0.2</mu1>
    <mu2>0.2</mu2>
    <selfCollide>true</selfCollide>
  </gazebo>
  <gazebo reference="front_left_1">
    <material>Gazebo/Silver</material>
    <mu1>0.2</mu1>
    <mu2>0.2</mu2>
    <selfCollide>true</selfCollide>
  </gazebo>
  <gazebo reference="laser_link_v1_1">
    <material>Gazebo/Silver</material>
    <mu1>0.2</mu1>
    <mu2>0.2</mu2>
    <selfCollide>true</selfCollide>
  </gazebo>
  <gazebo reference="camera_link_v1_1">
    <material>Gazebo/Silver</material>
    <mu1>0.2</mu1>
    <mu2>0.2</mu2>
    <selfCollide>true</selfCollide>
  </gazebo>
  

 !-- hokuyo --&gt;
  
  <gazebo reference="laser_link_v1_1">
    <sensor name="laser" type="ray">
      <pose>0 0 0 0 0 0</pose>
      <visualize>true</visualize>
      <update_rate>40</update_rate>
      <ray>
        <scan>
          <horizontal>
            <samples>720</samples>
            <resolution>1</resolution>
            <min_angle>-1.570796</min_angle>
            <max_angle>1.570796</max_angle>
          </horizontal>
        </scan>
        <range>
          <min>0.10</min>
          <max>30.0</max>
          <resolution>0.01</resolution>
        </range>
        <noise>
          <type>gaussian</type>
          <!-- Noise parameters based on published spec for Hokuyo laser
               achieving "+-30mm" accuracy at range < 10m.  A mean of 0.0m and
               stddev of 0.01m will put 99.7% of samples within 0.03m of the true
               reading. -->
          <mean>0.0</mean>
          <stddev>0.01</stddev>
        </noise>
      </ray>
      <plugin filename="libgazebo_ros_laser.so" name="gazebo_ros_head_hokuyo_controller">
        <topicName>scan</topicName>
        <frameName>laser_link_v1_1</frameName>
      </plugin>
    </sensor>
  </gazebo>
  <link name="base_link">
    <inertial>
      <origin rpy="0 0 0" xyz="0.0003147036812539107 8.654508451147519e-05 0.10819103947899564"/>
      <mass value="12.261671363009004"/>
      <inertia ixx="0.081478" ixy="-0.0" ixz="9.1e-05" iyy="0.132969" iyz="2.5e-05" izz="0.169987"/>
    </inertial>
    <visual>
      <origin rpy="0 0 0" xyz="0 0 0"/>
      <geometry>
        <mesh filename="package://navbot_description/meshes/base_link.stl" scale="0.001 0.001 0.001"/>
      </geometry>
      <material name="silver"/>
    </visual>
    <collision>
      <origin rpy="0 0 0" xyz="0 0 0"/>
      <geometry>
        <mesh filename="package://navbot_description/meshes/base_link.stl" scale="0.001 0.001 0.001"/>
      </geometry>
    </collision>
  </link>
  <link name="back_right_1">
    <inertial>
      <origin rpy="0 0 0" xyz="-4.597357573521421e-07 -0.02052480177758853 3.5268927792847515e-07"/>
      <mass value="4.878358553104739"/>
      <inertia ixx="0.006717" ixy="-0.0" ixz="-0.0" iyy="0.010579" iyz="-0.0" izz="0.006717"/>
    </inertial>
    <visual>
      <origin rpy="0 0 0" xyz="0.099572 0.149882 -0.060076"/>
      <geometry>
        <mesh filename="package://navbot_description/meshes/back_right_1.stl" scale="0.001 0.001 0.001"/>
      </geometry>
      <material name="silver"/>
    </visual>
    <collision>
      <origin rpy="0 0 0" xyz="0.099572 0.149882 -0.060076"/>
      <geometry>
        <mesh filename="package://navbot_description/meshes/back_right_1.stl" scale="0.001 0.001 0.001"/>
      </geometry>
    </collision>
  </link>
  <link name="front_right_1">
    <inertial>
      <origin rpy="0 0 0" xyz="-4.5917696378516837e-07 -0.02052480177758842 3.532853243698453e-07"/>
      <mass value="4.878358553104739"/>
      <inertia ixx="0.006717" ixy="-0.0" ixz="-0.0" iyy="0.010579" iyz="0.0" izz="0.006717"/>
    </inertial>
    <visual>
      <origin rpy="0 0 0" xyz="-0.100428 0.149882 -0.060076"/>
      <geometry>
        <mesh filename="package://navbot_description/meshes/front_right_1.stl" scale="0.001 0.001 0.001"/>
      </geometry>
      <material name="silver"/>
    </visual>
    <collision>
      <origin rpy="0 0 0" xyz="-0.100428 0.149882 -0.060076"/>
      <geometry>
        <mesh filename="package://navbot_description/meshes/front_right_1.stl" scale="0.001 0.001 0.001"/>
      </geometry>
    </collision>
  </link>
  <link name="back_left_1">
    <inertial>
      <origin rpy="0 0 0" xyz="-4.591769638545573e-07 0.02052395350161601 3.5268927771336944e-07"/>
      <mass value="4.878358553104739"/>
      <inertia ixx="0.006717" ixy="0.0" ixz="0.0" iyy="0.010579" iyz="0.0" izz="0.006717"/>
    </inertial>
    <visual>
      <origin rpy="0 0 0" xyz="0.099572 -0.150118 -0.060076"/>
      <geometry>
        <mesh filename="package://navbot_description/meshes/back_left_1.stl" scale="0.001 0.001 0.001"/>
      </geometry>
      <material name="silver"/>
    </visual>
    <collision>
      <origin rpy="0 0 0" xyz="0.099572 -0.150118 -0.060076"/>
      <geometry>
        <mesh filename="package://navbot_description/meshes/back_left_1.stl" scale="0.001 0.001 0.001"/>
      </geometry>
    </collision>
  </link>
  <link name="front_left_1">
    <inertial>
      <origin rpy="0 0 0" xyz="-4.5917696392394625e-07 0.020523953501616038 3.5328532416167846e-07"/>
      <mass value="4.878358553104739"/>
      <inertia ixx="0.006717" ixy="0.0" ixz="0.0" iyy="0.010579" iyz="0.0" izz="0.006717"/>
    </inertial>
    <visual>
      <origin rpy="0 0 0" xyz="-0.100428 -0.150118 -0.060076"/>
      <geometry>
        <mesh filename="package://navbot_description/meshes/front_left_1.stl" scale="0.001 0.001 0.001"/>
      </geometry>
      <material name="silver"/>
    </visual>
    <collision>
      <origin rpy="0 0 0" xyz="-0.100428 -0.150118 -0.060076"/>
      <geometry>
        <mesh filename="package://navbot_description/meshes/front_left_1.stl" scale="0.001 0.001 0.001"/>
      </geometry>
    </collision>
  </link>
  <link name="laser_link_v1_1">
    <inertial>
      <origin rpy="0 0 0" xyz="0.0002638330985168125 -0.0007615524008374664 0.020624066504128902"/>
      <mass value="1.6657432797148926"/>
      <inertia ixx="0.001074" ixy="0.0" ixz="-4e-06" iyy="0.001074" iyz="1.2e-05" izz="0.001371"/>
    </inertial>
    <visual>
      <origin rpy="0 0 0" xyz="-0.0 -0.0 -0.18"/>
      <geometry>
        <mesh filename="package://navbot_description/meshes/laser_link_v1_1.stl" scale="0.001 0.001 0.001"/>
      </geometry>
      <material name="silver"/>
    </visual>
    <collision>
      <origin rpy="0 0 0" xyz="-0.0 -0.0 -0.18"/>
      <geometry>
        <mesh filename="package://navbot_description/meshes/laser_link_v1_1.stl" scale="0.001 0.001 0.001"/>
      </geometry>
    </collision>
  </link>
  <link name="camera_link_v1_1">
    <inertial>
      <origin rpy="0 0 0" xyz="-0.010094496944980769 1.27997814036277e-05 -0.14999905153125456"/>
      <mass value="0.18735731616487916"/>
      <inertia ixx="0.000194" ixy="-0.0" ixz="-0.0" iyy="4e-05" iyz="0.0" izz="0.000155"/>
    </inertial>
    <visual>
      <origin rpy="0 0 0" xyz="-0.150428 -0.000118 -0.280076"/>
      <geometry>
        <mesh filename="package://navbot_description/meshes/camera_link_v1_1.stl" scale="0.001 0.001 0.001"/>
      </geometry>
      <material name="silver"/>
    </visual>
    <collision>
      <origin rpy="0 0 0" xyz="-0.150428 -0.000118 -0.280076"/>
      <geometry>
        <mesh filename="package://navbot_description/meshes/camera_link_v1_1.stl" scale="0.001 0.001 0.001"/>
      </geometry>
    </collision>
  </link>
  <joint name="Rev1" type="continuous">
    <origin rpy="0 0 0" xyz="-0.099572 -0.149882 0.060076"/>
    <parent link="base_link"/>
    <child link="back_right_1"/>
    <axis xyz="0.0 1.0 -0.0"/>
  </joint>
  <joint name="Rev3" type="continuous">
    <origin rpy="0 0 0" xyz="0.100428 -0.149882 0.060076"/>
    <parent link="base_link"/>
    <child link="front_right_1"/>
    <axis xyz="0.0 1.0 -0.0"/>
  </joint>
  <joint name="Rev4" type="continuous">
    <origin rpy="0 0 0" xyz="-0.099572 0.150118 0.060076"/>
    <parent link="base_link"/>
    <child link="back_left_1"/>
    <axis xyz="-0.0 1.0 0.0"/>
  </joint>
  <joint name="Rev5" type="continuous">
    <origin rpy="0 0 0" xyz="0.100428 0.150118 0.060076"/>
    <parent link="base_link"/>
    <child link="front_left_1"/>
    <axis xyz="-0.0 1.0 0.0"/>
  </joint>
  <joint name="Rigid8" type="fixed">
    <origin rpy="0 0 0" xyz="0.0 0.0 0.19"/>
    <parent link="base_link"/>
    <child link="laser_link_v1_1"/>
  </joint>
  <joint name="Rigid9" type="fixed">
    <origin rpy="0 0 0" xyz="0.150428 0.000118 0.280076"/>
    <parent link="base_link"/>
    <child link="camera_link_v1_1"/>
  </joint>
</robot>

